{"uid":"60d3a1be71ab2f56","name":"test_login_page_invalid_user","fullName":"tests.test_locked_user#test_login_page_invalid_user","historyId":"8899a35626a04237bb595183cff1415f","time":{"start":1755673312049,"stop":1755673312049,"duration":0},"description":"Testing locked user login and an error message","descriptionHtml":"<p>Testing locked user login and an error message</p>\n","status":"broken","statusMessage":"selenium.common.exceptions.SessionNotCreatedException: Message: session not created: probably user data directory is already in use, please specify a unique value for --user-data-dir argument, or don't use --user-data-dir; For documentation on this error, please visit: https://www.selenium.dev/documentation/webdriver/troubleshooting/errors#sessionnotcreatedexception\nStacktrace:\n#0 0x56392ae2d05a <unknown>\n#1 0x56392a8cca70 <unknown>\n#2 0x56392a907e07 <unknown>\n#3 0x56392a9025a7 <unknown>\n#4 0x56392a95293e <unknown>\n#5 0x56392a951f06 <unknown>\n#6 0x56392a9441b3 <unknown>\n#7 0x56392a91059b <unknown>\n#8 0x56392a911971 <unknown>\n#9 0x56392adf222b <unknown>\n#10 0x56392adf5f79 <unknown>\n#11 0x56392add9309 <unknown>\n#12 0x56392adf6b28 <unknown>\n#13 0x56392adbdbef <unknown>\n#14 0x56392ae1a0e8 <unknown>\n#15 0x56392ae1a2c6 <unknown>\n#16 0x56392ae2c036 <unknown>\n#17 0x7fdc09a9caa4 <unknown>\n#18 0x7fdc09b29c3c <unknown>","statusTrace":"@pytest.fixture(scope=\"session\")\n    def driver():\n        options = Options()\n    \n>       driver = webdriver.Chrome(options=options)\n\ntests/conftest.py:12: \n_ _ _ _ _ _ _ _ _ _ _ _ _ _ _ _ _ _ _ _ _ _ _ _ _ _ _ _ _ _ _ _ _ _ _ _ _ _ _ _ \n/opt/hostedtoolcache/Python/3.10.18/x64/lib/python3.10/site-packages/selenium/webdriver/chrome/webdriver.py:47: in __init__\n    super().__init__(\n/opt/hostedtoolcache/Python/3.10.18/x64/lib/python3.10/site-packages/selenium/webdriver/chromium/webdriver.py:69: in __init__\n    super().__init__(command_executor=executor, options=options)\n/opt/hostedtoolcache/Python/3.10.18/x64/lib/python3.10/site-packages/selenium/webdriver/remote/webdriver.py:263: in __init__\n    self.start_session(capabilities)\n/opt/hostedtoolcache/Python/3.10.18/x64/lib/python3.10/site-packages/selenium/webdriver/remote/webdriver.py:366: in start_session\n    response = self.execute(Command.NEW_SESSION, caps)[\"value\"]\n/opt/hostedtoolcache/Python/3.10.18/x64/lib/python3.10/site-packages/selenium/webdriver/remote/webdriver.py:458: in execute\n    self.error_handler.check_response(response)\n_ _ _ _ _ _ _ _ _ _ _ _ _ _ _ _ _ _ _ _ _ _ _ _ _ _ _ _ _ _ _ _ _ _ _ _ _ _ _ _ \n\nself = <selenium.webdriver.remote.errorhandler.ErrorHandler object at 0x7f77aceebca0>\nresponse = {'status': 500, 'value': '{\"value\":{\"error\":\"session not created\",\"message\":\"session not created: probably user data d...\\\\n#16 0x56392ae2c036 \\\\u003Cunknown>\\\\n#17 0x7fdc09a9caa4 \\\\u003Cunknown>\\\\n#18 0x7fdc09b29c3c \\\\u003Cunknown>\\\\n\"}}'}\n\n    def check_response(self, response: dict[str, Any]) -> None:\n        \"\"\"Checks that a JSON response from the WebDriver does not have an\n        error.\n    \n        :Args:\n         - response - The JSON response from the WebDriver server as a dictionary\n           object.\n    \n        :Raises: If the response contains an error message.\n        \"\"\"\n        status = response.get(\"status\", None)\n        if not status or status == ErrorCode.SUCCESS:\n            return\n        value = None\n        message = response.get(\"message\", \"\")\n        screen: str = response.get(\"screen\", \"\")\n        stacktrace = None\n        if isinstance(status, int):\n            value_json = response.get(\"value\", None)\n            if value_json and isinstance(value_json, str):\n                try:\n                    value = json.loads(value_json)\n                    if isinstance(value, dict):\n                        if len(value) == 1:\n                            value = value[\"value\"]\n                        status = value.get(\"error\", None)\n                        if not status:\n                            status = value.get(\"status\", ErrorCode.UNKNOWN_ERROR)\n                            message = value.get(\"value\") or value.get(\"message\")\n                            if not isinstance(message, str):\n                                value = message\n                                message = message.get(\"message\")\n                        else:\n                            message = value.get(\"message\", None)\n                except ValueError:\n                    pass\n    \n        exception_class: type[WebDriverException]\n        e = ErrorCode()\n        error_codes = [item for item in dir(e) if not item.startswith(\"__\")]\n        for error_code in error_codes:\n            error_info = getattr(ErrorCode, error_code)\n            if isinstance(error_info, list) and status in error_info:\n                exception_class = getattr(ExceptionMapping, error_code, WebDriverException)\n                break\n        else:\n            exception_class = WebDriverException\n    \n        if not value:\n            value = response[\"value\"]\n        if isinstance(value, str):\n            raise exception_class(value)\n        if message == \"\" and \"message\" in value:\n            message = value[\"message\"]\n    \n        screen = None  # type: ignore[assignment]\n        if \"screen\" in value:\n            screen = value[\"screen\"]\n    \n        stacktrace = None\n        st_value = value.get(\"stackTrace\") or value.get(\"stacktrace\")\n        if st_value:\n            if isinstance(st_value, str):\n                stacktrace = st_value.split(\"\\n\")\n            else:\n                stacktrace = []\n                try:\n                    for frame in st_value:\n                        line = frame.get(\"lineNumber\", \"\")\n                        file = frame.get(\"fileName\", \"<anonymous>\")\n                        if line:\n                            file = f\"{file}:{line}\"\n                        meth = frame.get(\"methodName\", \"<anonymous>\")\n                        if \"className\" in frame:\n                            meth = f\"{frame['className']}.{meth}\"\n                        msg = \"    at %s (%s)\"\n                        msg = msg % (meth, file)\n                        stacktrace.append(msg)\n                except TypeError:\n                    pass\n        if exception_class == UnexpectedAlertPresentException:\n            alert_text = None\n            if \"data\" in value:\n                alert_text = value[\"data\"].get(\"text\")\n            elif \"alert\" in value:\n                alert_text = value[\"alert\"].get(\"text\")\n            raise exception_class(message, screen, stacktrace, alert_text)  # type: ignore[call-arg]  # mypy is not smart enough here\n>       raise exception_class(message, screen, stacktrace)\nE       selenium.common.exceptions.SessionNotCreatedException: Message: session not created: probably user data directory is already in use, please specify a unique value for --user-data-dir argument, or don't use --user-data-dir; For documentation on this error, please visit: https://www.selenium.dev/documentation/webdriver/troubleshooting/errors#sessionnotcreatedexception\nE       Stacktrace:\nE       #0 0x56392ae2d05a <unknown>\nE       #1 0x56392a8cca70 <unknown>\nE       #2 0x56392a907e07 <unknown>\nE       #3 0x56392a9025a7 <unknown>\nE       #4 0x56392a95293e <unknown>\nE       #5 0x56392a951f06 <unknown>\nE       #6 0x56392a9441b3 <unknown>\nE       #7 0x56392a91059b <unknown>\nE       #8 0x56392a911971 <unknown>\nE       #9 0x56392adf222b <unknown>\nE       #10 0x56392adf5f79 <unknown>\nE       #11 0x56392add9309 <unknown>\nE       #12 0x56392adf6b28 <unknown>\nE       #13 0x56392adbdbef <unknown>\nE       #14 0x56392ae1a0e8 <unknown>\nE       #15 0x56392ae1a2c6 <unknown>\nE       #16 0x56392ae2c036 <unknown>\nE       #17 0x7fdc09a9caa4 <unknown>\nE       #18 0x7fdc09b29c3c <unknown>\n\n/opt/hostedtoolcache/Python/3.10.18/x64/lib/python3.10/site-packages/selenium/webdriver/remote/errorhandler.py:232: SessionNotCreatedException","flaky":false,"newFailed":false,"newBroken":false,"newPassed":false,"retriesCount":0,"retriesStatusChange":false,"beforeStages":[{"name":"driver","time":{"start":1755673308273,"stop":1755673311808,"duration":3535},"status":"broken","statusMessage":"selenium.common.exceptions.SessionNotCreatedException: Message: session not created: probably user data directory is already in use, please specify a unique value for --user-data-dir argument, or don't use --user-data-dir; For documentation on this error, please visit: https://www.selenium.dev/documentation/webdriver/troubleshooting/errors#sessionnotcreatedexception\nStacktrace:\n#0 0x56392ae2d05a <unknown>\n#1 0x56392a8cca70 <unknown>\n#2 0x56392a907e07 <unknown>\n#3 0x56392a9025a7 <unknown>\n#4 0x56392a95293e <unknown>\n#5 0x56392a951f06 <unknown>\n#6 0x56392a9441b3 <unknown>\n#7 0x56392a91059b <unknown>\n#8 0x56392a911971 <unknown>\n#9 0x56392adf222b <unknown>\n#10 0x56392adf5f79 <unknown>\n#11 0x56392add9309 <unknown>\n#12 0x56392adf6b28 <unknown>\n#13 0x56392adbdbef <unknown>\n#14 0x56392ae1a0e8 <unknown>\n#15 0x56392ae1a2c6 <unknown>\n#16 0x56392ae2c036 <unknown>\n#17 0x7fdc09a9caa4 <unknown>\n#18 0x7fdc09b29c3c <unknown>\n\n","statusTrace":"  File \"/opt/hostedtoolcache/Python/3.10.18/x64/lib/python3.10/site-packages/pluggy/_callers.py\", line 38, in run_old_style_hookwrapper\n    res = yield\n  File \"/opt/hostedtoolcache/Python/3.10.18/x64/lib/python3.10/site-packages/pluggy/_callers.py\", line 139, in _multicall\n    teardown.throw(exception)\n  File \"/opt/hostedtoolcache/Python/3.10.18/x64/lib/python3.10/site-packages/_pytest/setuponly.py\", line 36, in pytest_fixture_setup\n    return (yield)\n  File \"/opt/hostedtoolcache/Python/3.10.18/x64/lib/python3.10/site-packages/pluggy/_callers.py\", line 121, in _multicall\n    res = hook_impl.function(*args)\n  File \"/opt/hostedtoolcache/Python/3.10.18/x64/lib/python3.10/site-packages/_pytest/fixtures.py\", line 1195, in pytest_fixture_setup\n    result = call_fixture_func(fixturefunc, request, kwargs)\n  File \"/opt/hostedtoolcache/Python/3.10.18/x64/lib/python3.10/site-packages/_pytest/fixtures.py\", line 922, in call_fixture_func\n    fixture_result = next(generator)\n  File \"/home/runner/work/SauceDemoTest/SauceDemoTest/tests/conftest.py\", line 12, in driver\n    driver = webdriver.Chrome(options=options)\n  File \"/opt/hostedtoolcache/Python/3.10.18/x64/lib/python3.10/site-packages/selenium/webdriver/chrome/webdriver.py\", line 47, in __init__\n    super().__init__(\n  File \"/opt/hostedtoolcache/Python/3.10.18/x64/lib/python3.10/site-packages/selenium/webdriver/chromium/webdriver.py\", line 69, in __init__\n    super().__init__(command_executor=executor, options=options)\n  File \"/opt/hostedtoolcache/Python/3.10.18/x64/lib/python3.10/site-packages/selenium/webdriver/remote/webdriver.py\", line 263, in __init__\n    self.start_session(capabilities)\n  File \"/opt/hostedtoolcache/Python/3.10.18/x64/lib/python3.10/site-packages/selenium/webdriver/remote/webdriver.py\", line 366, in start_session\n    response = self.execute(Command.NEW_SESSION, caps)[\"value\"]\n  File \"/opt/hostedtoolcache/Python/3.10.18/x64/lib/python3.10/site-packages/selenium/webdriver/remote/webdriver.py\", line 458, in execute\n    self.error_handler.check_response(response)\n  File \"/opt/hostedtoolcache/Python/3.10.18/x64/lib/python3.10/site-packages/selenium/webdriver/remote/errorhandler.py\", line 232, in check_response\n    raise exception_class(message, screen, stacktrace)\n","steps":[],"attachments":[],"parameters":[],"shouldDisplayMessage":true,"stepsCount":0,"attachmentsCount":0,"hasContent":true,"attachmentStep":false},{"name":"test_data","time":{"start":1755673308273,"stop":1755673308273,"duration":0},"status":"passed","steps":[],"attachments":[],"parameters":[],"shouldDisplayMessage":false,"stepsCount":0,"attachmentsCount":0,"hasContent":false,"attachmentStep":false}],"afterStages":[],"labels":[{"name":"parentSuite","value":"tests"},{"name":"suite","value":"test_locked_user"},{"name":"host","value":"pkrvmubgrv54qmi"},{"name":"thread","value":"2117-MainThread"},{"name":"framework","value":"pytest"},{"name":"language","value":"cpython3"},{"name":"package","value":"tests.test_locked_user"},{"name":"resultFormat","value":"allure2"}],"parameters":[],"links":[],"hidden":false,"retry":false,"extra":{"severity":"normal","retries":[],"categories":[{"name":"Test defects","matchedStatuses":[]}],"tags":[]},"source":"60d3a1be71ab2f56.json","parameterValues":[]}